[2020-11-09 11:16:53,644] [autoreload.py:598] [autoreload:run_with_reloader] [INFO]- Watching for file changes with StatReloader
[2020-11-09 11:17:27,185] [autoreload.py:598] [autoreload:run_with_reloader] [INFO]- Watching for file changes with StatReloader
[2020-11-09 11:19:06,428] [autoreload.py:222] [autoreload:trigger_reload] [INFO]- D:\djangos\mysite\apps\user\urls.py changed, reloading.
[2020-11-09 11:19:07,526] [autoreload.py:598] [autoreload:run_with_reloader] [INFO]- Watching for file changes with StatReloader
[2020-11-09 11:19:20,953] [log.py:228] [log:log_response] [WARNING]- Not Found: /
[2020-11-09 11:19:20,953] [basehttp.py:157] [basehttp:log_message] [WARNING]- "GET / HTTP/1.1" 404 2337
[2020-11-09 11:19:20,990] [log.py:228] [log:log_response] [WARNING]- Not Found: /favicon.ico
[2020-11-09 11:19:20,991] [basehttp.py:157] [basehttp:log_message] [WARNING]- "GET /favicon.ico HTTP/1.1" 404 2388
[2020-11-09 11:19:32,806] [basehttp.py:157] [basehttp:log_message] [INFO]- "GET /user/add/ad HTTP/1.1" 301 0
[2020-11-09 11:19:32,995] [log.py:228] [log:log_response] [ERROR]- Internal Server Error: /user/add/ad/
Traceback (most recent call last):
  File "D:\20190930\envs\my_env\lib\site-packages\django\core\handlers\exception.py", line 34, in inner
    response = get_response(request)
  File "D:\20190930\envs\my_env\lib\site-packages\django\core\handlers\base.py", line 115, in _get_response
    response = self.process_exception_by_middleware(e, request)
  File "D:\20190930\envs\my_env\lib\site-packages\django\core\handlers\base.py", line 113, in _get_response
    response = wrapped_callback(request, *callback_args, **callback_kwargs)
TypeError: __init__() takes 1 positional argument but 2 were given
[2020-11-09 11:19:32,996] [basehttp.py:157] [basehttp:log_message] [ERROR]- "GET /user/add/ad/ HTTP/1.1" 500 71636
[2020-11-09 11:20:31,666] [autoreload.py:222] [autoreload:trigger_reload] [INFO]- D:\djangos\mysite\apps\user\serializer.py changed, reloading.
[2020-11-09 11:20:32,838] [autoreload.py:598] [autoreload:run_with_reloader] [INFO]- Watching for file changes with StatReloader
[2020-11-09 11:20:34,931] [log.py:228] [log:log_response] [ERROR]- Internal Server Error: /user/add/ad/
Traceback (most recent call last):
  File "D:\20190930\envs\my_env\lib\site-packages\django\core\handlers\exception.py", line 34, in inner
    response = get_response(request)
  File "D:\20190930\envs\my_env\lib\site-packages\django\core\handlers\base.py", line 115, in _get_response
    response = self.process_exception_by_middleware(e, request)
  File "D:\20190930\envs\my_env\lib\site-packages\django\core\handlers\base.py", line 113, in _get_response
    response = wrapped_callback(request, *callback_args, **callback_kwargs)
TypeError: __init__() takes 1 positional argument but 2 were given
[2020-11-09 11:20:34,933] [basehttp.py:157] [basehttp:log_message] [ERROR]- "GET /user/add/ad/ HTTP/1.1" 500 71773
[2020-11-09 11:21:04,959] [autoreload.py:222] [autoreload:trigger_reload] [INFO]- D:\djangos\mysite\apps\user\serializer.py changed, reloading.
[2020-11-09 11:21:06,115] [autoreload.py:598] [autoreload:run_with_reloader] [INFO]- Watching for file changes with StatReloader
[2020-11-09 11:21:06,872] [basehttp.py:157] [basehttp:log_message] [INFO]- "GET /v2/index_entry?geohash=&group_type=1&flags[]=F HTTP/1.1" 301 0
[2020-11-09 11:21:06,872] [basehttp.py:157] [basehttp:log_message] [INFO]- "GET /v1/user?user_id=null HTTP/1.1" 301 0
[2020-11-09 11:21:06,901] [basehttp.py:157] [basehttp:log_message] [INFO]- "GET /v1/user/?user_id=null HTTP/1.1" 200 39
[2020-11-09 11:21:07,108] [basehttp.py:157] [basehttp:log_message] [INFO]- "GET /v2/index_entry/?geohash=&group_type=1&flags[]=F HTTP/1.1" 200 10719
[2020-11-09 11:21:29,347] [log.py:228] [log:log_response] [WARNING]- Not Found: /
[2020-11-09 11:21:29,348] [basehttp.py:157] [basehttp:log_message] [WARNING]- "GET / HTTP/1.1" 404 2337
[2020-11-09 11:21:44,005] [autoreload.py:598] [autoreload:run_with_reloader] [INFO]- Watching for file changes with StatReloader
[2020-11-09 11:21:59,013] [basehttp.py:157] [basehttp:log_message] [INFO]- "GET /user/add/ad HTTP/1.1" 301 0
[2020-11-09 11:21:59,181] [log.py:228] [log:log_response] [ERROR]- Internal Server Error: /user/add/ad/
Traceback (most recent call last):
  File "D:\20190930\envs\my_env\lib\site-packages\django\core\handlers\exception.py", line 34, in inner
    response = get_response(request)
  File "D:\20190930\envs\my_env\lib\site-packages\django\core\handlers\base.py", line 115, in _get_response
    response = self.process_exception_by_middleware(e, request)
  File "D:\20190930\envs\my_env\lib\site-packages\django\core\handlers\base.py", line 113, in _get_response
    response = wrapped_callback(request, *callback_args, **callback_kwargs)
TypeError: __init__() takes 1 positional argument but 2 were given
[2020-11-09 11:21:59,182] [basehttp.py:157] [basehttp:log_message] [ERROR]- "GET /user/add/ad/ HTTP/1.1" 500 71636
[2020-11-09 11:21:59,215] [log.py:228] [log:log_response] [WARNING]- Not Found: /favicon.ico
[2020-11-09 11:21:59,215] [basehttp.py:157] [basehttp:log_message] [WARNING]- "GET /favicon.ico HTTP/1.1" 404 2388
[2020-11-09 11:22:28,881] [log.py:228] [log:log_response] [ERROR]- Internal Server Error: /user/add/ad/
Traceback (most recent call last):
  File "D:\20190930\envs\my_env\lib\site-packages\django\core\handlers\exception.py", line 34, in inner
    response = get_response(request)
  File "D:\20190930\envs\my_env\lib\site-packages\django\core\handlers\base.py", line 115, in _get_response
    response = self.process_exception_by_middleware(e, request)
  File "D:\20190930\envs\my_env\lib\site-packages\django\core\handlers\base.py", line 113, in _get_response
    response = wrapped_callback(request, *callback_args, **callback_kwargs)
TypeError: __init__() takes 1 positional argument but 2 were given
[2020-11-09 11:22:28,882] [basehttp.py:157] [basehttp:log_message] [ERROR]- "GET /user/add/ad/ HTTP/1.1" 500 71773
[2020-11-09 11:23:39,598] [autoreload.py:598] [autoreload:run_with_reloader] [INFO]- Watching for file changes with StatReloader
[2020-11-09 11:23:52,871] [autoreload.py:598] [autoreload:run_with_reloader] [INFO]- Watching for file changes with StatReloader
[2020-11-09 11:24:02,267] [log.py:228] [log:log_response] [WARNING]- Not Found: /
[2020-11-09 11:24:02,268] [basehttp.py:157] [basehttp:log_message] [WARNING]- "GET / HTTP/1.1" 404 2337
[2020-11-09 11:24:02,290] [log.py:228] [log:log_response] [WARNING]- Not Found: /favicon.ico
[2020-11-09 11:24:02,291] [basehttp.py:157] [basehttp:log_message] [WARNING]- "GET /favicon.ico HTTP/1.1" 404 2388
[2020-11-09 11:24:06,616] [log.py:228] [log:log_response] [WARNING]- Not Found: /user
[2020-11-09 11:24:06,617] [basehttp.py:157] [basehttp:log_message] [WARNING]- "GET /user HTTP/1.1" 404 2367
[2020-11-09 11:24:58,685] [log.py:228] [log:log_response] [WARNING]- Not Found: /user/add
[2020-11-09 11:24:58,686] [basehttp.py:157] [basehttp:log_message] [WARNING]- "GET /user/add HTTP/1.1" 404 2435
[2020-11-09 11:25:03,453] [basehttp.py:157] [basehttp:log_message] [INFO]- "GET /user/add/ad HTTP/1.1" 301 0
[2020-11-09 11:25:03,602] [log.py:228] [log:log_response] [ERROR]- Internal Server Error: /user/add/ad/
Traceback (most recent call last):
  File "D:\20190930\envs\my_env\lib\site-packages\django\core\handlers\exception.py", line 34, in inner
    response = get_response(request)
  File "D:\20190930\envs\my_env\lib\site-packages\django\core\handlers\base.py", line 115, in _get_response
    response = self.process_exception_by_middleware(e, request)
  File "D:\20190930\envs\my_env\lib\site-packages\django\core\handlers\base.py", line 113, in _get_response
    response = wrapped_callback(request, *callback_args, **callback_kwargs)
TypeError: __init__() takes 1 positional argument but 2 were given
[2020-11-09 11:25:03,604] [basehttp.py:157] [basehttp:log_message] [ERROR]- "GET /user/add/ad/ HTTP/1.1" 500 71636
[2020-11-09 11:25:30,803] [autoreload.py:222] [autoreload:trigger_reload] [INFO]- D:\djangos\mysite\apps\user\urls.py changed, reloading.
[2020-11-09 11:25:31,953] [autoreload.py:598] [autoreload:run_with_reloader] [INFO]- Watching for file changes with StatReloader
[2020-11-09 11:25:33,093] [basehttp.py:157] [basehttp:log_message] [INFO]- "GET /user/add/ad/ HTTP/1.1" 200 14480
[2020-11-09 11:25:33,110] [basehttp.py:157] [basehttp:log_message] [INFO]- "GET /static/rest_framework/css/bootstrap-tweaks.css HTTP/1.1" 200 3385
[2020-11-09 11:25:33,118] [basehttp.py:157] [basehttp:log_message] [INFO]- "GET /static/rest_framework/css/prettify.css HTTP/1.1" 200 817
[2020-11-09 11:25:33,119] [basehttp.py:157] [basehttp:log_message] [INFO]- "GET /static/rest_framework/js/prettify-min.js HTTP/1.1" 200 13632
[2020-11-09 11:25:33,122] [basehttp.py:157] [basehttp:log_message] [INFO]- "GET /static/rest_framework/css/default.css HTTP/1.1" 200 1131
[2020-11-09 11:25:33,124] [basehttp.py:157] [basehttp:log_message] [INFO]- "GET /static/rest_framework/css/bootstrap.min.css HTTP/1.1" 200 121457
[2020-11-09 11:25:33,127] [basehttp.py:157] [basehttp:log_message] [INFO]- "GET /static/rest_framework/js/ajax-form.js HTTP/1.1" 200 3597
[2020-11-09 11:25:33,128] [basehttp.py:157] [basehttp:log_message] [INFO]- "GET /static/rest_framework/js/csrf.js HTTP/1.1" 200 1719
[2020-11-09 11:25:33,130] [basehttp.py:157] [basehttp:log_message] [INFO]- "GET /static/rest_framework/js/default.js HTTP/1.1" 200 1268
[2020-11-09 11:25:33,130] [basehttp.py:157] [basehttp:log_message] [INFO]- "GET /static/rest_framework/js/bootstrap.min.js HTTP/1.1" 200 39680
[2020-11-09 11:25:33,131] [basehttp.py:157] [basehttp:log_message] [INFO]- "GET /static/rest_framework/js/jquery-3.5.1.min.js HTTP/1.1" 200 89476
[2020-11-09 11:25:33,143] [basehttp.py:157] [basehttp:log_message] [INFO]- "GET /static/rest_framework/img/grid.png HTTP/1.1" 200 1458
[2020-11-09 11:26:50,060] [basehttp.py:157] [basehttp:log_message] [INFO]- "POST /user/add/ad/ HTTP/1.1" 201 14878
[2020-11-09 14:38:38,038] [autoreload.py:222] [autoreload:trigger_reload] [INFO]- D:\djangos\mysite\apps\user\urls.py changed, reloading.
[2020-11-09 14:38:39,288] [autoreload.py:598] [autoreload:run_with_reloader] [INFO]- Watching for file changes with StatReloader
[2020-11-09 15:02:21,787] [autoreload.py:598] [autoreload:run_with_reloader] [INFO]- Watching for file changes with StatReloader
[2020-11-09 15:03:21,664] [autoreload.py:598] [autoreload:run_with_reloader] [INFO]- Watching for file changes with StatReloader
[2020-11-09 15:03:36,701] [basehttp.py:157] [basehttp:log_message] [INFO]- "GET /v1/cities?type=guess HTTP/1.1" 301 0
[2020-11-09 15:03:36,713] [basehttp.py:157] [basehttp:log_message] [INFO]- "GET /v2/index_entry?geohash=&group_type=1&flags[]=F HTTP/1.1" 301 0
[2020-11-09 15:04:14,102] [autoreload.py:598] [autoreload:run_with_reloader] [INFO]- Watching for file changes with StatReloader
[2020-11-09 15:04:42,813] [basehttp.py:157] [basehttp:log_message] [INFO]- "GET /user/userinfo?type=guess&geohash=28.227779%2C112.938858 HTTP/1.1" 301 0
[2020-11-09 15:04:42,827] [views.py:24] [views:list] [ERROR]- user_id is must number
[2020-11-09 15:04:42,828] [basehttp.py:157] [basehttp:log_message] [INFO]- "GET /user/userinfo/?type=guess&geohash=28.227779%2C112.938858 HTTP/1.1" 200 35
[2020-11-09 15:07:00,770] [basehttp.py:157] [basehttp:log_message] [INFO]- "GET /v1/cities?type=guess HTTP/1.1" 301 0
[2020-11-09 15:07:00,780] [basehttp.py:157] [basehttp:log_message] [INFO]- "GET /user/userinfo?user_id=null HTTP/1.1" 301 0
[2020-11-09 15:07:00,783] [basehttp.py:157] [basehttp:log_message] [INFO]- "GET /v2/index_entry?geohash=&group_type=1&flags[]=F HTTP/1.1" 301 0
[2020-11-09 15:07:00,883] [views.py:24] [views:list] [ERROR]- user_id is must number
[2020-11-09 15:07:00,884] [basehttp.py:157] [basehttp:log_message] [INFO]- "GET /user/userinfo/?user_id=null HTTP/1.1" 200 35
[2020-11-09 15:07:28,063] [autoreload.py:598] [autoreload:run_with_reloader] [INFO]- Watching for file changes with StatReloader
[2020-11-09 15:10:07,261] [basehttp.py:157] [basehttp:log_message] [INFO]- "GET /user/userinfo?type=guess&geohash=28.227779%2C112.938858 HTTP/1.1" 301 0
[2020-11-09 15:10:07,271] [views.py:24] [views:list] [ERROR]- user_id is must number
[2020-11-09 15:10:07,272] [basehttp.py:157] [basehttp:log_message] [INFO]- "GET /user/userinfo/?type=guess&geohash=28.227779%2C112.938858 HTTP/1.1" 200 35
[2020-11-09 15:10:20,398] [basehttp.py:157] [basehttp:log_message] [INFO]- "GET /user/userinfo?type=guess&geohash=28.227779%2C112.938858&user_id=123456 HTTP/1.1" 301 0
[2020-11-09 15:10:20,746] [log.py:228] [log:log_response] [ERROR]- Internal Server Error: /user/userinfo/
Traceback (most recent call last):
  File "D:\20190930\envs\my_env\lib\site-packages\django\core\handlers\exception.py", line 34, in inner
    response = get_response(request)
  File "D:\20190930\envs\my_env\lib\site-packages\django\core\handlers\base.py", line 145, in _get_response
    response = self.process_exception_by_middleware(e, request)
  File "D:\20190930\envs\my_env\lib\site-packages\django\core\handlers\base.py", line 143, in _get_response
    response = response.render()
  File "D:\20190930\envs\my_env\lib\site-packages\django\template\response.py", line 105, in render
    self.content = self.rendered_content
  File "D:\20190930\envs\my_env\lib\site-packages\rest_framework\response.py", line 70, in rendered_content
    ret = renderer.render(self.data, accepted_media_type, context)
  File "D:\20190930\envs\my_env\lib\site-packages\rest_framework\renderers.py", line 103, in render
    allow_nan=not self.strict, separators=separators
  File "D:\20190930\envs\my_env\lib\site-packages\rest_framework\utils\json.py", line 25, in dumps
    return json.dumps(*args, **kwargs)
  File "c:\users\15827\appdata\local\programs\python\python37\Lib\json\__init__.py", line 238, in dumps
    **kw).encode(obj)
  File "c:\users\15827\appdata\local\programs\python\python37\Lib\json\encoder.py", line 199, in encode
    chunks = self.iterencode(o, _one_shot=True)
  File "c:\users\15827\appdata\local\programs\python\python37\Lib\json\encoder.py", line 257, in iterencode
    return _iterencode(o, 0)
  File "D:\20190930\envs\my_env\lib\site-packages\rest_framework\utils\encoders.py", line 67, in default
    return super().default(obj)
  File "c:\users\15827\appdata\local\programs\python\python37\Lib\json\encoder.py", line 179, in default
    raise TypeError(f'Object of type {o.__class__.__name__} '
TypeError: Object of type Uses is not JSON serializable
[2020-11-09 15:10:20,751] [basehttp.py:157] [basehttp:log_message] [ERROR]- "GET /user/userinfo/?type=guess&geohash=28.227779%2C112.938858&user_id=123456 HTTP/1.1" 500 110582
[2020-11-09 15:11:21,289] [autoreload.py:222] [autoreload:trigger_reload] [INFO]- D:\djangos\mysite\apps\user\views.py changed, reloading.
[2020-11-09 15:11:22,536] [autoreload.py:598] [autoreload:run_with_reloader] [INFO]- Watching for file changes with StatReloader
[2020-11-09 15:13:06,618] [autoreload.py:222] [autoreload:trigger_reload] [INFO]- D:\djangos\mysite\apps\user\views.py changed, reloading.
[2020-11-09 15:13:07,757] [autoreload.py:598] [autoreload:run_with_reloader] [INFO]- Watching for file changes with StatReloader
[2020-11-09 15:13:09,043] [basehttp.py:157] [basehttp:log_message] [INFO]- "GET /user/userinfo?type=guess&geohash=28.227779%2C112.938858&user_id=123456 HTTP/1.1" 301 0
[2020-11-09 15:13:09,239] [views.py:33] [views:list] [INFO]- user_id is not find
[2020-11-09 15:13:09,239] [basehttp.py:157] [basehttp:log_message] [INFO]- "GET /user/userinfo/?type=guess&geohash=28.227779%2C112.938858&user_id=123456 HTTP/1.1" 200 47
[2020-11-09 15:13:17,208] [basehttp.py:157] [basehttp:log_message] [INFO]- "GET /user/userinfo?type=guess&geohash=28.227779%2C112.938858&user_id=123456 HTTP/1.1" 301 0
[2020-11-09 15:13:17,414] [views.py:33] [views:list] [INFO]- user_id is not find
[2020-11-09 15:13:17,414] [basehttp.py:157] [basehttp:log_message] [INFO]- "GET /user/userinfo/?type=guess&geohash=28.227779%2C112.938858&user_id=123456 HTTP/1.1" 200 47
[2020-11-09 15:13:37,158] [autoreload.py:222] [autoreload:trigger_reload] [INFO]- D:\djangos\mysite\apps\user\views.py changed, reloading.
[2020-11-09 15:13:38,414] [autoreload.py:598] [autoreload:run_with_reloader] [INFO]- Watching for file changes with StatReloader
[2020-11-09 15:13:40,820] [basehttp.py:157] [basehttp:log_message] [INFO]- "GET /user/userinfo?type=guess&geohash=28.227779%2C112.938858&user_id=123456 HTTP/1.1" 301 0
[2020-11-09 15:13:41,156] [log.py:228] [log:log_response] [ERROR]- Internal Server Error: /user/userinfo/
Traceback (most recent call last):
  File "D:\20190930\envs\my_env\lib\site-packages\django\core\handlers\exception.py", line 34, in inner
    response = get_response(request)
  File "D:\20190930\envs\my_env\lib\site-packages\django\core\handlers\base.py", line 115, in _get_response
    response = self.process_exception_by_middleware(e, request)
  File "D:\20190930\envs\my_env\lib\site-packages\django\core\handlers\base.py", line 113, in _get_response
    response = wrapped_callback(request, *callback_args, **callback_kwargs)
  File "D:\20190930\envs\my_env\lib\site-packages\django\views\decorators\csrf.py", line 54, in wrapped_view
    return view_func(*args, **kwargs)
  File "D:\20190930\envs\my_env\lib\site-packages\rest_framework\viewsets.py", line 125, in view
    return self.dispatch(request, *args, **kwargs)
  File "D:\20190930\envs\my_env\lib\site-packages\rest_framework\views.py", line 509, in dispatch
    response = self.handle_exception(exc)
  File "D:\20190930\envs\my_env\lib\site-packages\rest_framework\views.py", line 469, in handle_exception
    self.raise_uncaught_exception(exc)
  File "D:\20190930\envs\my_env\lib\site-packages\rest_framework\views.py", line 480, in raise_uncaught_exception
    raise exc
  File "D:\20190930\envs\my_env\lib\site-packages\rest_framework\views.py", line 506, in dispatch
    response = handler(request, *args, **kwargs)
  File "D:\djangos\mysite\apps\user\views.py", line 36, in list
    for i in queryset:
TypeError: 'Uses' object is not iterable
[2020-11-09 15:13:41,160] [basehttp.py:157] [basehttp:log_message] [ERROR]- "GET /user/userinfo/?type=guess&geohash=28.227779%2C112.938858&user_id=123456 HTTP/1.1" 500 19944
[2020-11-09 15:13:54,835] [autoreload.py:222] [autoreload:trigger_reload] [INFO]- D:\djangos\mysite\apps\user\views.py changed, reloading.
[2020-11-09 15:13:55,952] [autoreload.py:598] [autoreload:run_with_reloader] [INFO]- Watching for file changes with StatReloader
[2020-11-09 15:13:57,324] [basehttp.py:157] [basehttp:log_message] [INFO]- "GET /user/userinfo?type=guess&geohash=28.227779%2C112.938858&user_id=123456 HTTP/1.1" 301 0
[2020-11-09 15:13:57,661] [log.py:228] [log:log_response] [ERROR]- Internal Server Error: /user/userinfo/
Traceback (most recent call last):
  File "D:\20190930\envs\my_env\lib\site-packages\django\core\handlers\exception.py", line 34, in inner
    response = get_response(request)
  File "D:\20190930\envs\my_env\lib\site-packages\django\core\handlers\base.py", line 115, in _get_response
    response = self.process_exception_by_middleware(e, request)
  File "D:\20190930\envs\my_env\lib\site-packages\django\core\handlers\base.py", line 113, in _get_response
    response = wrapped_callback(request, *callback_args, **callback_kwargs)
  File "D:\20190930\envs\my_env\lib\site-packages\django\views\decorators\csrf.py", line 54, in wrapped_view
    return view_func(*args, **kwargs)
  File "D:\20190930\envs\my_env\lib\site-packages\rest_framework\viewsets.py", line 125, in view
    return self.dispatch(request, *args, **kwargs)
  File "D:\20190930\envs\my_env\lib\site-packages\rest_framework\views.py", line 509, in dispatch
    response = self.handle_exception(exc)
  File "D:\20190930\envs\my_env\lib\site-packages\rest_framework\views.py", line 469, in handle_exception
    self.raise_uncaught_exception(exc)
  File "D:\20190930\envs\my_env\lib\site-packages\rest_framework\views.py", line 480, in raise_uncaught_exception
    raise exc
  File "D:\20190930\envs\my_env\lib\site-packages\rest_framework\views.py", line 506, in dispatch
    response = handler(request, *args, **kwargs)
  File "D:\djangos\mysite\apps\user\views.py", line 36, in list
    print(list(queryset))
TypeError: 'Uses' object is not iterable
[2020-11-09 15:13:57,663] [basehttp.py:157] [basehttp:log_message] [ERROR]- "GET /user/userinfo/?type=guess&geohash=28.227779%2C112.938858&user_id=123456 HTTP/1.1" 500 19947
[2020-11-09 15:14:12,224] [autoreload.py:222] [autoreload:trigger_reload] [INFO]- D:\djangos\mysite\apps\user\views.py changed, reloading.
[2020-11-09 15:14:13,385] [autoreload.py:598] [autoreload:run_with_reloader] [INFO]- Watching for file changes with StatReloader
[2020-11-09 15:14:14,491] [basehttp.py:157] [basehttp:log_message] [INFO]- "GET /user/userinfo?type=guess&geohash=28.227779%2C112.938858&user_id=123456 HTTP/1.1" 301 0
[2020-11-09 15:14:14,822] [log.py:228] [log:log_response] [ERROR]- Internal Server Error: /user/userinfo/
Traceback (most recent call last):
  File "D:\20190930\envs\my_env\lib\site-packages\django\core\handlers\exception.py", line 34, in inner
    response = get_response(request)
  File "D:\20190930\envs\my_env\lib\site-packages\django\core\handlers\base.py", line 115, in _get_response
    response = self.process_exception_by_middleware(e, request)
  File "D:\20190930\envs\my_env\lib\site-packages\django\core\handlers\base.py", line 113, in _get_response
    response = wrapped_callback(request, *callback_args, **callback_kwargs)
  File "D:\20190930\envs\my_env\lib\site-packages\django\views\decorators\csrf.py", line 54, in wrapped_view
    return view_func(*args, **kwargs)
  File "D:\20190930\envs\my_env\lib\site-packages\rest_framework\viewsets.py", line 125, in view
    return self.dispatch(request, *args, **kwargs)
  File "D:\20190930\envs\my_env\lib\site-packages\rest_framework\views.py", line 509, in dispatch
    response = self.handle_exception(exc)
  File "D:\20190930\envs\my_env\lib\site-packages\rest_framework\views.py", line 469, in handle_exception
    self.raise_uncaught_exception(exc)
  File "D:\20190930\envs\my_env\lib\site-packages\rest_framework\views.py", line 480, in raise_uncaught_exception
    raise exc
  File "D:\20190930\envs\my_env\lib\site-packages\rest_framework\views.py", line 506, in dispatch
    response = handler(request, *args, **kwargs)
  File "D:\djangos\mysite\apps\user\views.py", line 37, in list
    print(list(queryset))
TypeError: 'Uses' object is not iterable
[2020-11-09 15:14:14,825] [basehttp.py:157] [basehttp:log_message] [ERROR]- "GET /user/userinfo/?type=guess&geohash=28.227779%2C112.938858&user_id=123456 HTTP/1.1" 500 19947
[2020-11-09 15:14:25,740] [autoreload.py:222] [autoreload:trigger_reload] [INFO]- D:\djangos\mysite\apps\user\views.py changed, reloading.
[2020-11-09 15:14:26,873] [autoreload.py:598] [autoreload:run_with_reloader] [INFO]- Watching for file changes with StatReloader
[2020-11-09 15:14:29,259] [basehttp.py:157] [basehttp:log_message] [INFO]- "GET /user/userinfo?type=guess&geohash=28.227779%2C112.938858&user_id=123456 HTTP/1.1" 301 0
[2020-11-09 15:14:29,598] [log.py:228] [log:log_response] [ERROR]- Internal Server Error: /user/userinfo/
Traceback (most recent call last):
  File "D:\20190930\envs\my_env\lib\site-packages\django\core\handlers\exception.py", line 34, in inner
    response = get_response(request)
  File "D:\20190930\envs\my_env\lib\site-packages\django\core\handlers\base.py", line 145, in _get_response
    response = self.process_exception_by_middleware(e, request)
  File "D:\20190930\envs\my_env\lib\site-packages\django\core\handlers\base.py", line 143, in _get_response
    response = response.render()
  File "D:\20190930\envs\my_env\lib\site-packages\django\template\response.py", line 105, in render
    self.content = self.rendered_content
  File "D:\20190930\envs\my_env\lib\site-packages\rest_framework\response.py", line 70, in rendered_content
    ret = renderer.render(self.data, accepted_media_type, context)
  File "D:\20190930\envs\my_env\lib\site-packages\rest_framework\renderers.py", line 103, in render
    allow_nan=not self.strict, separators=separators
  File "D:\20190930\envs\my_env\lib\site-packages\rest_framework\utils\json.py", line 25, in dumps
    return json.dumps(*args, **kwargs)
  File "c:\users\15827\appdata\local\programs\python\python37\Lib\json\__init__.py", line 238, in dumps
    **kw).encode(obj)
  File "c:\users\15827\appdata\local\programs\python\python37\Lib\json\encoder.py", line 199, in encode
    chunks = self.iterencode(o, _one_shot=True)
  File "c:\users\15827\appdata\local\programs\python\python37\Lib\json\encoder.py", line 257, in iterencode
    return _iterencode(o, 0)
  File "D:\20190930\envs\my_env\lib\site-packages\rest_framework\utils\encoders.py", line 67, in default
    return super().default(obj)
  File "c:\users\15827\appdata\local\programs\python\python37\Lib\json\encoder.py", line 179, in default
    raise TypeError(f'Object of type {o.__class__.__name__} '
TypeError: Object of type Uses is not JSON serializable
[2020-11-09 15:14:29,603] [basehttp.py:157] [basehttp:log_message] [ERROR]- "GET /user/userinfo/?type=guess&geohash=28.227779%2C112.938858&user_id=123456 HTTP/1.1" 500 110582
[2020-11-09 15:14:43,670] [basehttp.py:157] [basehttp:log_message] [INFO]- "GET /user/userinfo?type=guess&geohash=28.227779%2C112.938858&user_id=123456 HTTP/1.1" 301 0
[2020-11-09 15:14:43,888] [log.py:228] [log:log_response] [ERROR]- Internal Server Error: /user/userinfo/
Traceback (most recent call last):
  File "D:\20190930\envs\my_env\lib\site-packages\django\core\handlers\exception.py", line 34, in inner
    response = get_response(request)
  File "D:\20190930\envs\my_env\lib\site-packages\django\core\handlers\base.py", line 145, in _get_response
    response = self.process_exception_by_middleware(e, request)
  File "D:\20190930\envs\my_env\lib\site-packages\django\core\handlers\base.py", line 143, in _get_response
    response = response.render()
  File "D:\20190930\envs\my_env\lib\site-packages\django\template\response.py", line 105, in render
    self.content = self.rendered_content
  File "D:\20190930\envs\my_env\lib\site-packages\rest_framework\response.py", line 70, in rendered_content
    ret = renderer.render(self.data, accepted_media_type, context)
  File "D:\20190930\envs\my_env\lib\site-packages\rest_framework\renderers.py", line 103, in render
    allow_nan=not self.strict, separators=separators
  File "D:\20190930\envs\my_env\lib\site-packages\rest_framework\utils\json.py", line 25, in dumps
    return json.dumps(*args, **kwargs)
  File "c:\users\15827\appdata\local\programs\python\python37\Lib\json\__init__.py", line 238, in dumps
    **kw).encode(obj)
  File "c:\users\15827\appdata\local\programs\python\python37\Lib\json\encoder.py", line 199, in encode
    chunks = self.iterencode(o, _one_shot=True)
  File "c:\users\15827\appdata\local\programs\python\python37\Lib\json\encoder.py", line 257, in iterencode
    return _iterencode(o, 0)
  File "D:\20190930\envs\my_env\lib\site-packages\rest_framework\utils\encoders.py", line 67, in default
    return super().default(obj)
  File "c:\users\15827\appdata\local\programs\python\python37\Lib\json\encoder.py", line 179, in default
    raise TypeError(f'Object of type {o.__class__.__name__} '
TypeError: Object of type Uses is not JSON serializable
[2020-11-09 15:14:43,892] [basehttp.py:157] [basehttp:log_message] [ERROR]- "GET /user/userinfo/?type=guess&geohash=28.227779%2C112.938858&user_id=123456 HTTP/1.1" 500 110582
[2020-11-09 15:19:15,103] [autoreload.py:222] [autoreload:trigger_reload] [INFO]- D:\djangos\mysite\apps\user\views.py changed, reloading.
[2020-11-09 15:19:16,274] [autoreload.py:598] [autoreload:run_with_reloader] [INFO]- Watching for file changes with StatReloader
[2020-11-09 15:19:32,492] [autoreload.py:222] [autoreload:trigger_reload] [INFO]- D:\djangos\mysite\apps\user\urls.py changed, reloading.
[2020-11-09 15:19:33,712] [autoreload.py:598] [autoreload:run_with_reloader] [INFO]- Watching for file changes with StatReloader
[2020-11-09 15:19:35,340] [basehttp.py:157] [basehttp:log_message] [INFO]- "GET /user/userinfo?type=guess&geohash=28.227779%2C112.938858&user_id=123456 HTTP/1.1" 301 0
[2020-11-09 15:19:35,540] [basehttp.py:157] [basehttp:log_message] [INFO]- "GET /user/userinfo/?type=guess&geohash=28.227779%2C112.938858&user_id=123456 HTTP/1.1" 200 8
[2020-11-09 15:20:24,915] [autoreload.py:222] [autoreload:trigger_reload] [INFO]- D:\djangos\mysite\apps\user\serializer.py changed, reloading.
[2020-11-09 15:20:26,045] [autoreload.py:598] [autoreload:run_with_reloader] [INFO]- Watching for file changes with StatReloader
[2020-11-09 15:20:26,827] [basehttp.py:157] [basehttp:log_message] [INFO]- "GET /user/userinfo?type=guess&geohash=28.227779%2C112.938858&user_id=123456 HTTP/1.1" 301 0
[2020-11-09 15:20:27,137] [basehttp.py:157] [basehttp:log_message] [INFO]- "GET /user/userinfo/?type=guess&geohash=28.227779%2C112.938858&user_id=123456 HTTP/1.1" 200 345
[2020-11-09 15:23:11,989] [basehttp.py:157] [basehttp:log_message] [INFO]- "GET /v1/cities?type=guess HTTP/1.1" 301 0
[2020-11-09 15:23:12,016] [basehttp.py:157] [basehttp:log_message] [INFO]- "GET /user/userinfo?user_id=null HTTP/1.1" 301 0
[2020-11-09 15:23:12,020] [basehttp.py:157] [basehttp:log_message] [INFO]- "GET /v2/index_entry?geohash=&group_type=1&flags[]=F HTTP/1.1" 301 0
[2020-11-09 15:23:12,167] [views.py:25] [views:list] [ERROR]- user_id is must number
[2020-11-09 15:23:12,170] [basehttp.py:157] [basehttp:log_message] [INFO]- "GET /user/userinfo/?user_id=null HTTP/1.1" 200 35
